<?xml version='1.0'?>
<sdf version='1.6'>
  <model name="MobRob">
    <static>false</static>

    <link name='chassis'>
      <pose>0 0 .1 0 0 0</pose>

      <collision name='chassis_collision'>
        <geometry>
          <box>
            <size>.2 .1 .1</size>
          </box>
        </geometry>
      </collision>

      <visual name='visual'>
        <geometry>
          <box>
            <size>.4 .2 .1</size>
          </box>
        </geometry>
        <material>
          <script>
            <name>Gazebo/Yellow</name>
            <uri>file://media/materials/scripts/gazebo.material</uri>
          </script>
        </material>
      </visual>

      <!-- Collision sensor -->
      <sensor name='contact_sensor_chassis' type='contact'>
        <contact>
          <collision>chassis_collision</collision>
        </contact>
        <always_on>1</always_on>
        <update_rate>1000.0</update_rate>
      </sensor>

      <collision name='caster_collision'>
        <pose>-0.15 0 -0.05 0 0 0</pose>
        <geometry>
            <sphere>
            <radius>.05</radius>
          </sphere>
        </geometry>

        <surface>
          <friction>
            <ode>
              <mu>0</mu>
              <mu2>0</mu2>
              <slip1>1.0</slip1>
              <slip2>1.0</slip2>
            </ode>
          </friction>
        </surface>
      </collision>

      <visual name='caster_visual'>
        <pose>-0.15 0 -0.05 0 0 0</pose>
        <geometry>
          <sphere>
            <radius>.05</radius>
          </sphere>
        </geometry>
        <material>
          <script>
            <name>Gazebo/Gray</name>
            <uri>file://media/materials/scripts/gazebo.material</uri>
          </script>
        </material>
      </visual>
    </link>

    <link name="left_wheel">
      <pose>0.1 -0.13 0.1 0 1.5707 1.5707</pose>
      <collision name="left_wheel_collision">
        <geometry>
          <cylinder>
            <radius>.1</radius>
            <length>.05</length>
          </cylinder>
        </geometry>
      </collision>
      <visual name="visual">
        <geometry>
          <cylinder>
            <radius>.1</radius>
            <length>.05</length>
          </cylinder>
        </geometry>
        <material>
          <script>
            <name>Gazebo/Gray</name>
            <uri>file://media/materials/scripts/gazebo.material</uri>
          </script>
        </material>
      </visual>
      <!-- Collision sensor -->
      <sensor name='contact_sensor_wheel_left' type='contact'>
        <contact>
          <collision>left_wheel_collision</collision>
        </contact>
        <always_on>1</always_on>
        <update_rate>1000.0</update_rate>
      </sensor>
    </link>

    <link name="right_wheel">
      <pose>0.1 0.13 0.1 0 1.5707 1.5707</pose>
      <collision name="right_wheel_collision">
        <geometry>
          <cylinder>
            <radius>.1</radius>
            <length>.05</length>
          </cylinder>
        </geometry>
      </collision>
      <visual name="visual">
        <geometry>
          <cylinder>
            <radius>.1</radius>
            <length>.05</length>
          </cylinder>
        </geometry>
        <material>
          <script>
            <name>Gazebo/Gray</name>
            <uri>file://media/materials/scripts/gazebo.material</uri>
          </script>
        </material>
      </visual>
      <!-- Collision sensor -->
      <sensor name='contact_sensor_wheel_right' type='contact'>
        <contact>
          <collision>right_wheel_collision</collision>
        </contact>
        <always_on>1</always_on>
        <update_rate>1000.0</update_rate>
      </sensor>
    </link>

    <joint type="revolute" name="left_wheel_hinge">
      <pose>0 0 -0.03 0 0 0</pose>
      <child>left_wheel</child>
      <parent>chassis</parent>
      <axis>
        <xyz>0 1 0</xyz>
      </axis>
    </joint>

    <joint type="revolute" name="right_wheel_hinge">
      <pose>0 0 0.03 0 0 0</pose>
      <child>right_wheel</child>
      <parent>chassis</parent>
      <axis>
        <xyz>0 1 0</xyz>
      </axis>
    </joint>

    <include>
      <uri>model://camera</uri>
      <pose>-0.15 0 0.2 0 0 3.14159265359</pose>
      <image>
        <width>1024</width>
        <height>768</height>
      </image>
    </include>
    <joint name="camera_joint" type="fixed">
      <child>camera::link</child>
      <parent>chassis</parent>
    </joint>

  </model>
</sdf>